Workbook

Sheet Guide
A1: Portfolio Tracker
A2: Manual version · Strategies Lab · base currency EUR
B4: What it does | C4: Tracks a multi-asset portfolio in EUR: positions and P&L, allocation vs targets, monthly performance vs a benchmark, risk metrics (volatility, drawdown, VaR, Expected Shortfall, beta, tracking error) and a decision journal.
B5: Colour code | C5: Blue text = input you type. Black text = formula, do not overwrite. Green text = link to another sheet. Yellow fill = key setting. Light orange rows = example data to replace.
B6: 1 · Settings | C6: Set the portfolio name, benchmark, risk-free rate, VaR confidence level, rebalancing threshold and target weight per strategy.
B7: 2 · Transactions | C7: Log every deposit, withdrawal, buy, sell, dividend and fee, one row each. Quantities and cash are derived from this sheet only.
B8: 3 · Holdings | C8: List each instrument once (ticker in column A). Quantity, cost, value, weight, P&L and the rebalancing action are calculated. Type the name, quote currency, last price and FX rate (units of currency per 1 EUR).
B9: 4 · History | C9: At each month end, type the date and the portfolio's total value (Dashboard, cell B6). External flows come from Transactions; returns use the Modified Dietz method. Type the benchmark level at the same date.
B10: 5 · Read | C10: Dashboard: summary and charts. Risk: every ratio with what it means. Allocation: actual vs target by asset class, strategy, region and currency. Journal: decisions and reasons.
B11: Monthly routine | C11: 1) Log the month's transactions. 2) Refresh prices (type last prices and FX). 3) Copy the total value into History. 4) Check the Action column in Holdings and the deviations in Allocation. 5) Write one line in the Journal.
B12: Method notes | C12: Monthly return (Modified Dietz) = (V_end − V_start − Flow) / (V_start + 0.5 × Flow). Annualised volatility = monthly standard deviation × √12. Sharpe = mean monthly excess return × 12 / annualised volatility. Historical VaR = loss not exceeded in (confidence)% of months; ES = average loss beyond the VaR. Risk metrics need at least 12 months of history to be meaningful.
B13: Limitations | C13: Average cost uses buys only (realised P&L on sells is not tracked separately). FX for cost is the rate typed on each transaction. Monthly data understate intra-month drawdowns.
B15: This workbook is a tool, not investment advice. Example figures are illustrative only.

Sheet Dashboard
A1: =Settings!B4
A2: Summary of value, performance, risk and allocation. All figures update from the other sheets.
A3: ="As of "&TEXT(IFERROR(LOOKUP(9.99E+307,History!$A$6:$A$185),TODAY()),"dd mmm yyyy")&" · benchmark: "&Settings!B6
B5: Total value | D5: Net deposits | F5: Gain since inception | H5: Total return (TWR) | J5: Year to date | L5: Annualised return
B6: =Holdings!B5 | D6: =SUMIFS(Transactions!$J$6:$J$505,Transactions!$B$6:$B$505,"Deposit")-SUMIFS(Transactions!$J$6:$J$505,Transactions!$B$6:$B$505,"Withdrawal") | F6: =B6-D6 | H6: =Risk!B6 | J6: =Risk!B8 | L6: =Risk!B7
B9: Volatility (ann.) | D9: Sharpe ratio | F9: Max drawdown | H9: VaR monthly | J9: Beta vs benchmark | L9: Positions / cash
B10: =Risk!B9 | D10: =Risk!B10 | F10: =Risk!B12 | H10: =Risk!B15 | J10: =Risk!B20 | L10: =TEXT(Holdings!B6,"0")&" / "&TEXT(Risk!B35,"0%")
B13: Charts: portfolio vs benchmark, drawdown, monthly returns, allocation and top holdings. Risk details in the Risk sheet.

Sheet Holdings
A1: Holdings
A2: One row per instrument. Type the ticker, classification and target weight; the rest is calculated from Transactions and the prices you type.
A3: Invested value | B3: =SUM(K8:K47) | D3: Rows with a ticker but zero quantity are kept and shown as closed.
A4: Cash (from Transactions) | B4: =SUM(Transactions!$K$6:$K$505)
A5: Total portfolio value | B5: =B3+B4
A6: Number of positions | B6: =COUNTIF(G8:G47,">0")
A7: Ticker | B7: Name | C7: Asset class | D7: Strategy | E7: Region | F7: Quote currency | G7: Quantity | H7: Avg cost (EUR / unit) | I7: Last price (quote ccy) | J7: FX (ccy per 1 EUR) | K7: Market value (EUR) | L7: Weight | M7: Cost basis (EUR) | N7: Unrealised P&L (EUR) | O7: P&L % | P7: 1-day change | Q7: YTD change | R7: Target weight | S7: Deviation | T7: Action | U7: Comment
A8: IWDA LN Equity | B8: iShares Core MSCI World UCITS ETF (Acc) | C8: Equity | D8: Value strategy | E8: Global | F8: USD | G8: =IF(A8="","",SUMIFS(Transactions!$D$6:$D$505,Transactions!$C$6:$C$505,A8,Transactions!$B$6:$B$505,"Buy")-SUMIFS(Transactions!$D$6:$D$505,Transactions!$C$6:$C$505,A8,Transactions!$B$6:$B$505,"Sell")) | H8: =IF(A8="","",IFERROR((SUMIFS(Transactions!$I$6:$I$505,Transactions!$C$6:$C$505,A8,Transactions!$B$6:$B$505,"Buy")+SUMIFS(Transactions!$H$6:$H$505,Transactions!$C$6:$C$505,A8,Transactions!$B$6:$B$505,"Buy"))/SUMIFS(Transactions!$D$6:$D$505,Transactions!$C$6:$C$505,A8,Transactions!$B$6:$B$505,"Buy"),0)) | I8: 112.4 | J8: 1.133 | K8: =IF(A8="","",IFERROR(G8*I8*IF(EXACT(F8,"GBp"),0.01,1)/J8,0)) | L8: =IF(A8="","",IFERROR(K8/$B$5,0)) | M8: =IF(A8="","",G8*H8) | N8: =IF(A8="","",K8-M8) | O8: =IF(A8="","",IFERROR(N8/M8,0)) | R8: 0.4 | S8: =IF(A8="","",L8-R8) | T8: =IF(A8="","",IF(ABS(S8)<=Settings!$B$10,"OK",IF(S8>0,"Sell ","Buy ")&TEXT(ABS(S8)*$B$5,"#,##0")&" €")) | U8: Example — replace
A9: EXS1 GY Equity | B9: iShares Core DAX UCITS ETF (DE) | C9: Equity | D9: Value strategy | E9: Europe | F9: EUR | G9: =IF(A9="","",SUMIFS(Transactions!$D$6:$D$505,Transactions!$C$6:$C$505,A9,Transactions!$B$6:$B$505,"Buy")-SUMIFS(Transactions!$D$6:$D$505,Transactions!$C$6:$C$505,A9,Transactions!$B$6:$B$505,"Sell")) | H9: =IF(A9="","",IFERROR((SUMIFS(Transactions!$I$6:$I$505,Transactions!$C$6:$C$505,A9,Transactions!$B$6:$B$505,"Buy")+SUMIFS(Transactions!$H$6:$H$505,Transactions!$C$6:$C$505,A9,Transactions!$B$6:$B$505,"Buy"))/SUMIFS(Transactions!$D$6:$D$505,Transactions!$C$6:$C$505,A9,Transactions!$B$6:$B$505,"Buy"),0)) | I9: 205.1 | J9: 1 | K9: =IF(A9="","",IFERROR(G9*I9*IF(EXACT(F9,"GBp"),0.01,1)/J9,0)) | L9: =IF(A9="","",IFERROR(K9/$B$5,0)) | M9: =IF(A9="","",G9*H9) | N9: =IF(A9="","",K9-M9) | O9: =IF(A9="","",IFERROR(N9/M9,0)) | R9: 0.16 | S9: =IF(A9="","",L9-R9) | T9: =IF(A9="","",IF(ABS(S9)<=Settings!$B$10,"OK",IF(S9>0,"Sell ","Buy ")&TEXT(ABS(S9)*$B$5,"#,##0")&" €")) | U9: Example — replace
A10: SGLN LN Equity | B10: iShares Physical Gold ETC | C10: Commodity | D10: Trend ETF | E10: Global | F10: GBp | G10: =IF(A10="","",SUMIFS(Transactions!$D$6:$D$505,Transactions!$C$6:$C$505,A10,Transactions!$B$6:$B$505,"Buy")-SUMIFS(Transactions!$D$6:$D$505,Transactions!$C$6:$C$505,A10,Transactions!$B$6:$B$505,"Sell")) | H10: =IF(A10="","",IFERROR((SUMIFS(Transactions!$I$6:$I$505,Transactions!$C$6:$C$505,A10,Transactions!$B$6:$B$505,"Buy")+SUMIFS(Transactions!$H$6:$H$505,Transactions!$C$6:$C$505,A10,Transactions!$B$6:$B$505,"Buy"))/SUMIFS(Transactions!$D$6:$D$505,Transactions!$C$6:$C$505,A10,Transactions!$B$6:$B$505,"Buy"),0)) | I10: 6180 | J10: 0.854 | K10: =IF(A10="","",IFERROR(G10*I10*IF(EXACT(F10,"GBp"),0.01,1)/J10,0)) | L10: =IF(A10="","",IFERROR(K10/$B$5,0)) | M10: =IF(A10="","",G10*H10) | N10: =IF(A10="","",K10-M10) | O10: =IF(A10="","",IFERROR(N10/M10,0)) | R10: 0.12 | S10: =IF(A10="","",L10-R10) | T10: =IF(A10="","",IF(ABS(S10)<=Settings!$B$10,"OK",IF(S10>0,"Sell ","Buy ")&TEXT(ABS(S10)*$B$5,"#,##0")&" €")) | U10: Example — replace
A11: IBTM LN Equity | B11: iShares $ Treasury Bond 7-10yr UCITS ETF | C11: Bond | D11: Trend ETF | E11: North America | F11: USD | G11: =IF(A11="","",SUMIFS(Transactions!$D$6:$D$505,Transactions!$C$6:$C$505,A11,Transactions!$B$6:$B$505,"Buy")-SUMIFS(Transactions!$D$6:$D$505,Transactions!$C$6:$C$505,A11,Transactions!$B$6:$B$505,"Sell")) | H11: =IF(A11="","",IFERROR((SUMIFS(Transactions!$I$6:$I$505,Transactions!$C$6:$C$505,A11,Transactions!$B$6:$B$505,"Buy")+SUMIFS(Transactions!$H$6:$H$505,Transactions!$C$6:$C$505,A11,Transactions!$B$6:$B$505,"Buy"))/SUMIFS(Transactions!$D$6:$D$505,Transactions!$C$6:$C$505,A11,Transactions!$B$6:$B$505,"Buy"),0)) | I11: 168.2 | J11: 1.133 | K11: =IF(A11="","",IFERROR(G11*I11*IF(EXACT(F11,"GBp"),0.01,1)/J11,0)) | L11: =IF(A11="","",IFERROR(K11/$B$5,0)) | M11: =IF(A11="","",G11*H11) | N11: =IF(A11="","",K11-M11) | O11: =IF(A11="","",IFERROR(N11/M11,0)) | R11: 0.12 | S11: =IF(A11="","",L11-R11) | T11: =IF(A11="","",IF(ABS(S11)<=Settings!$B$10,"OK",IF(S11>0,"Sell ","Buy ")&TEXT(ABS(S11)*$B$5,"#,##0")&" €")) | U11: Example — replace
A12: XEON GY Equity | B12: Xtrackers II EUR Overnight Rate Swap UCITS ETF | C12: Money market | D12: Cash & money market | E12: Europe | F12: EUR | G12: =IF(A12="","",SUMIFS(Transactions!$D$6:$D$505,Transactions!$C$6:$C$505,A12,Transactions!$B$6:$B$505,"Buy")-SUMIFS(Transactions!$D$6:$D$505,Transactions!$C$6:$C$505,A12,Transactions!$B$6:$B$505,"Sell")) | H12: =IF(A12="","",IFERROR((SUMIFS(Transactions!$I$6:$I$505,Transactions!$C$6:$C$505,A12,Transactions!$B$6:$B$505,"Buy")+SUMIFS(Transactions!$H$6:$H$505,Transactions!$C$6:$C$505,A12,Transactions!$B$6:$B$505,"Buy"))/SUMIFS(Transactions!$D$6:$D$505,Transactions!$C$6:$C$505,A12,Transactions!$B$6:$B$505,"Buy"),0)) | I12: 149.3 | J12: 1 | K12: =IF(A12="","",IFERROR(G12*I12*IF(EXACT(F12,"GBp"),0.01,1)/J12,0)) | L12: =IF(A12="","",IFERROR(K12/$B$5,0)) | M12: =IF(A12="","",G12*H12) | N12: =IF(A12="","",K12-M12) | O12: =IF(A12="","",IFERROR(N12/M12,0)) | R12: 0.15 | S12: =IF(A12="","",L12-R12) | T12: =IF(A12="","",IF(ABS(S12)<=Settings!$B$10,"OK",IF(S12>0,"Sell ","Buy ")&TEXT(ABS(S12)*$B$5,"#,##0")&" €")) | U12: Example — replace
G13: =IF(A13="","",SUMIFS(Transactions!$D$6:$D$505,Transactions!$C$6:$C$505,A13,Transactions!$B$6:$B$505,"Buy")-SUMIFS(Transactions!$D$6:$D$505,Transactions!$C$6:$C$505,A13,Transactions!$B$6:$B$505,"Sell")) | H13: =IF(A13="","",IFERROR((SUMIFS(Transactions!$I$6:$I$505,Transactions!$C$6:$C$505,A13,Transactions!$B$6:$B$505,"Buy")+SUMIFS(Transactions!$H$6:$H$505,Transactions!$C$6:$C$505,A13,Transactions!$B$6:$B$505,"Buy"))/SUMIFS(Transactions!$D$6:$D$505,Transactions!$C$6:$C$505,A13,Transactions!$B$6:$B$505,"Buy"),0)) | K13: =IF(A13="","",IFERROR(G13*I13*IF(EXACT(F13,"GBp"),0.01,1)/J13,0)) | L13: =IF(A13="","",IFERROR(K13/$B$5,0)) | M13: =IF(A13="","",G13*H13) | N13: =IF(A13="","",K13-M13) | O13: =IF(A13="","",IFERROR(N13/M13,0)) | S13: =IF(A13="","",L13-R13) | T13: =IF(A13="","",IF(ABS(S13)<=Settings!$B$10,"OK",IF(S13>0,"Sell ","Buy ")&TEXT(ABS(S13)*$B$5,"#,##0")&" €"))
G14: =IF(A14="","",SUMIFS(Transactions!$D$6:$D$505,Transactions!$C$6:$C$505,A14,Transactions!$B$6:$B$505,"Buy")-SUMIFS(Transactions!$D$6:$D$505,Transactions!$C$6:$C$505,A14,Transactions!$B$6:$B$505,"Sell")) | H14: =IF(A14="","",IFERROR((SUMIFS(Transactions!$I$6:$I$505,Transactions!$C$6:$C$505,A14,Transactions!$B$6:$B$505,"Buy")+SUMIFS(Transactions!$H$6:$H$505,Transactions!$C$6:$C$505,A14,Transactions!$B$6:$B$505,"Buy"))/SUMIFS(Transactions!$D$6:$D$505,Transactions!$C$6:$C$505,A14,Transactions!$B$6:$B$505,"Buy"),0)) | K14: =IF(A14="","",IFERROR(G14*I14*IF(EXACT(F14,"GBp"),0.01,1)/J14,0)) | L14: =IF(A14="","",IFERROR(K14/$B$5,0)) | M14: =IF(A14="","",G14*H14) | N14: =IF(A14="","",K14-M14) | O14: =IF(A14="","",IFERROR(N14/M14,0)) | S14: =IF(A14="","",L14-R14) | T14: =IF(A14="","",IF(ABS(S14)<=Settings!$B$10,"OK",IF(S14>0,"Sell ","Buy ")&TEXT(ABS(S14)*$B$5,"#,##0")&" €"))
G15: =IF(A15="","",SUMIFS(Transactions!$D$6:$D$505,Transactions!$C$6:$C$505,A15,Transactions!$B$6:$B$505,"Buy")-SUMIFS(Transactions!$D$6:$D$505,Transactions!$C$6:$C$505,A15,Transactions!$B$6:$B$505,"Sell")) | H15: =IF(A15="","",IFERROR((SUMIFS(Transactions!$I$6:$I$505,Transactions!$C$6:$C$505,A15,Transactions!$B$6:$B$505,"Buy")+SUMIFS(Transactions!$H$6:$H$505,Transactions!$C$6:$C$505,A15,Transactions!$B$6:$B$505,"Buy"))/SUMIFS(Transactions!$D$6:$D$505,Transactions!$C$6:$C$505,A15,Transactions!$B$6:$B$505,"Buy"),0)) | K15: =IF(A15="","",IFERROR(G15*I15*IF(EXACT(F15,"GBp"),0.01,1)/J15,0)) | L15: =IF(A15="","",IFERROR(K15/$B$5,0)) | M15: =IF(A15="","",G15*H15) | N15: =IF(A15="","",K15-M15) | O15: =IF(A15="","",IFERROR(N15/M15,0)) | S15: =IF(A15="","",L15-R15) | T15: =IF(A15="","",IF(ABS(S15)<=Settings!$B$10,"OK",IF(S15>0,"Sell ","Buy ")&TEXT(ABS(S15)*$B$5,"#,##0")&" €"))
G16: =IF(A16="","",SUMIFS(Transactions!$D$6:$D$505,Transactions!$C$6:$C$505,A16,Transactions!$B$6:$B$505,"Buy")-SUMIFS(Transactions!$D$6:$D$505,Transactions!$C$6:$C$505,A16,Transactions!$B$6:$B$505,"Sell")) | H16: =IF(A16="","",IFERROR((SUMIFS(Transactions!$I$6:$I$505,Transactions!$C$6:$C$505,A16,Transactions!$B$6:$B$505,"Buy")+SUMIFS(Transactions!$H$6:$H$505,Transactions!$C$6:$C$505,A16,Transactions!$B$6:$B$505,"Buy"))/SUMIFS(Transactions!$D$6:$D$505,Transactions!$C$6:$C$505,A16,Transactions!$B$6:$B$505,"Buy"),0)) | K16: =IF(A16="","",IFERROR(G16*I16*IF(EXACT(F16,"GBp"),0.01,1)/J16,0)) | L16: =IF(A16="","",IFERROR(K16/$B$5,0)) | M16: =IF(A16="","",G16*H16) | N16: =IF(A16="","",K16-M16) | O16: =IF(A16="","",IFERROR(N16/M16,0)) | S16: =IF(A16="","",L16-R16) | T16: =IF(A16="","",IF(ABS(S16)<=Settings!$B$10,"OK",IF(S16>0,"Sell ","Buy ")&TEXT(ABS(S16)*$B$5,"#,##0")&" €"))
G17: =IF(A17="","",SUMIFS(Transactions!$D$6:$D$505,Transactions!$C$6:$C$505,A17,Transactions!$B$6:$B$505,"Buy")-SUMIFS(Transactions!$D$6:$D$505,Transactions!$C$6:$C$505,A17,Transactions!$B$6:$B$505,"Sell")) | H17: =IF(A17="","",IFERROR((SUMIFS(Transactions!$I$6:$I$505,Transactions!$C$6:$C$505,A17,Transactions!$B$6:$B$505,"Buy")+SUMIFS(Transactions!$H$6:$H$505,Transactions!$C$6:$C$505,A17,Transactions!$B$6:$B$505,"Buy"))/SUMIFS(Transactions!$D$6:$D$505,Transactions!$C$6:$C$505,A17,Transactions!$B$6:$B$505,"Buy"),0)) | K17: =IF(A17="","",IFERROR(G17*I17*IF(EXACT(F17,"GBp"),0.01,1)/J17,0)) | L17: =IF(A17="","",IFERROR(K17/$B$5,0)) | M17: =IF(A17="","",G17*H17) | N17: =IF(A17="","",K17-M17) | O17: =IF(A17="","",IFERROR(N17/M17,0)) | S17: =IF(A17="","",L17-R17) | T17: =IF(A17="","",IF(ABS(S17)<=Settings!$B$10,"OK",IF(S17>0,"Sell ","Buy ")&TEXT(ABS(S17)*$B$5,"#,##0")&" €"))
G18: =IF(A18="","",SUMIFS(Transactions!$D$6:$D$505,Transactions!$C$6:$C$505,A18,Transactions!$B$6:$B$505,"Buy")-SUMIFS(Transactions!$D$6:$D$505,Transactions!$C$6:$C$505,A18,Transactions!$B$6:$B$505,"Sell")) | H18: =IF(A18="","",IFERROR((SUMIFS(Transactions!$I$6:$I$505,Transactions!$C$6:$C$505,A18,Transactions!$B$6:$B$505,"Buy")+SUMIFS(Transactions!$H$6:$H$505,Transactions!$C$6:$C$505,A18,Transactions!$B$6:$B$505,"Buy"))/SUMIFS(Transactions!$D$6:$D$505,Transactions!$C$6:$C$505,A18,Transactions!$B$6:$B$505,"Buy"),0)) | K18: =IF(A18="","",IFERROR(G18*I18*IF(EXACT(F18,"GBp"),0.01,1)/J18,0)) | L18: =IF(A18="","",IFERROR(K18/$B$5,0)) | M18: =IF(A18="","",G18*H18) | N18: =IF(A18="","",K18-M18) | O18: =IF(A18="","",IFERROR(N18/M18,0)) | S18: =IF(A18="","",L18-R18) | T18: =IF(A18="","",IF(ABS(S18)<=Settings!$B$10,"OK",IF(S18>0,"Sell ","Buy ")&TEXT(ABS(S18)*$B$5,"#,##0")&" €"))
G19: =IF(A19="","",SUMIFS(Transactions!$D$6:$D$505,Transactions!$C$6:$C$505,A19,Transactions!$B$6:$B$505,"Buy")-SUMIFS(Transactions!$D$6:$D$505,Transactions!$C$6:$C$505,A19,Transactions!$B$6:$B$505,"Sell")) | H19: =IF(A19="","",IFERROR((SUMIFS(Transactions!$I$6:$I$505,Transactions!$C$6:$C$505,A19,Transactions!$B$6:$B$505,"Buy")+SUMIFS(Transactions!$H$6:$H$505,Transactions!$C$6:$C$505,A19,Transactions!$B$6:$B$505,"Buy"))/SUMIFS(Transactions!$D$6:$D$505,Transactions!$C$6:$C$505,A19,Transactions!$B$6:$B$505,"Buy"),0)) | K19: =IF(A19="","",IFERROR(G19*I19*IF(EXACT(F19,"GBp"),0.01,1)/J19,0)) | L19: =IF(A19="","",IFERROR(K19/$B$5,0)) | M19: =IF(A19="","",G19*H19) | N19: =IF(A19="","",K19-M19) | O19: =IF(A19="","",IFERROR(N19/M19,0)) | S19: =IF(A19="","",L19-R19) | T19: =IF(A19="","",IF(ABS(S19)<=Settings!$B$10,"OK",IF(S19>0,"Sell ","Buy ")&TEXT(ABS(S19)*$B$5,"#,##0")&" €"))
G20: =IF(A20="","",SUMIFS(Transactions!$D$6:$D$505,Transactions!$C$6:$C$505,A20,Transactions!$B$6:$B$505,"Buy")-SUMIFS(Transactions!$D$6:$D$505,Transactions!$C$6:$C$505,A20,Transactions!$B$6:$B$505,"Sell")) | H20: =IF(A20="","",IFERROR((SUMIFS(Transactions!$I$6:$I$505,Transactions!$C$6:$C$505,A20,Transactions!$B$6:$B$505,"Buy")+SUMIFS(Transactions!$H$6:$H$505,Transactions!$C$6:$C$505,A20,Transactions!$B$6:$B$505,"Buy"))/SUMIFS(Transactions!$D$6:$D$505,Transactions!$C$6:$C$505,A20,Transactions!$B$6:$B$505,"Buy"),0)) | K20: =IF(A20="","",IFERROR(G20*I20*IF(EXACT(F20,"GBp"),0.01,1)/J20,0)) | L20: =IF(A20="","",IFERROR(K20/$B$5,0)) | M20: =IF(A20="","",G20*H20) | N20: =IF(A20="","",K20-M20) | O20: =IF(A20="","",IFERROR(N20/M20,0)) | S20: =IF(A20="","",L20-R20) | T20: =IF(A20="","",IF(ABS(S20)<=Settings!$B$10,"OK",IF(S20>0,"Sell ","Buy ")&TEXT(ABS(S20)*$B$5,"#,##0")&" €"))
G21: =IF(A21="","",SUMIFS(Transactions!$D$6:$D$505,Transactions!$C$6:$C$505,A21,Transactions!$B$6:$B$505,"Buy")-SUMIFS(Transactions!$D$6:$D$505,Transactions!$C$6:$C$505,A21,Transactions!$B$6:$B$505,"Sell")) | H21: =IF(A21="","",IFERROR((SUMIFS(Transactions!$I$6:$I$505,Transactions!$C$6:$C$505,A21,Transactions!$B$6:$B$505,"Buy")+SUMIFS(Transactions!$H$6:$H$505,Transactions!$C$6:$C$505,A21,Transactions!$B$6:$B$505,"Buy"))/SUMIFS(Transactions!$D$6:$D$505,Transactions!$C$6:$C$505,A21,Transactions!$B$6:$B$505,"Buy"),0)) | K21: =IF(A21="","",IFERROR(G21*I21*IF(EXACT(F21,"GBp"),0.01,1)/J21,0)) | L21: =IF(A21="","",IFERROR(K21/$B$5,0)) | M21: =IF(A21="","",G21*H21) | N21: =IF(A21="","",K21-M21) | O21: =IF(A21="","",IFERROR(N21/M21,0)) | S21: =IF(A21="","",L21-R21) | T21: =IF(A21="","",IF(ABS(S21)<=Settings!$B$10,"OK",IF(S21>0,"Sell ","Buy ")&TEXT(ABS(S21)*$B$5,"#,##0")&" €"))
G22: =IF(A22="","",SUMIFS(Transactions!$D$6:$D$505,Transactions!$C$6:$C$505,A22,Transactions!$B$6:$B$505,"Buy")-SUMIFS(Transactions!$D$6:$D$505,Transactions!$C$6:$C$505,A22,Transactions!$B$6:$B$505,"Sell")) | H22: =IF(A22="","",IFERROR((SUMIFS(Transactions!$I$6:$I$505,Transactions!$C$6:$C$505,A22,Transactions!$B$6:$B$505,"Buy")+SUMIFS(Transactions!$H$6:$H$505,Transactions!$C$6:$C$505,A22,Transactions!$B$6:$B$505,"Buy"))/SUMIFS(Transactions!$D$6:$D$505,Transactions!$C$6:$C$505,A22,Transactions!$B$6:$B$505,"Buy"),0)) | K22: =IF(A22="","",IFERROR(G22*I22*IF(EXACT(F22,"GBp"),0.01,1)/J22,0)) | L22: =IF(A22="","",IFERROR(K22/$B$5,0)) | M22: =IF(A22="","",G22*H22) | N22: =IF(A22="","",K22-M22) | O22: =IF(A22="","",IFERROR(N22/M22,0)) | S22: =IF(A22="","",L22-R22) | T22: =IF(A22="","",IF(ABS(S22)<=Settings!$B$10,"OK",IF(S22>0,"Sell ","Buy ")&TEXT(ABS(S22)*$B$5,"#,##0")&" €"))
G23: =IF(A23="","",SUMIFS(Transactions!$D$6:$D$505,Transactions!$C$6:$C$505,A23,Transactions!$B$6:$B$505,"Buy")-SUMIFS(Transactions!$D$6:$D$505,Transactions!$C$6:$C$505,A23,Transactions!$B$6:$B$505,"Sell")) | H23: =IF(A23="","",IFERROR((SUMIFS(Transactions!$I$6:$I$505,Transactions!$C$6:$C$505,A23,Transactions!$B$6:$B$505,"Buy")+SUMIFS(Transactions!$H$6:$H$505,Transactions!$C$6:$C$505,A23,Transactions!$B$6:$B$505,"Buy"))/SUMIFS(Transactions!$D$6:$D$505,Transactions!$C$6:$C$505,A23,Transactions!$B$6:$B$505,"Buy"),0)) | K23: =IF(A23="","",IFERROR(G23*I23*IF(EXACT(F23,"GBp"),0.01,1)/J23,0)) | L23: =IF(A23="","",IFERROR(K23/$B$5,0)) | M23: =IF(A23="","",G23*H23) | N23: =IF(A23="","",K23-M23) | O23: =IF(A23="","",IFERROR(N23/M23,0)) | S23: =IF(A23="","",L23-R23) | T23: =IF(A23="","",IF(ABS(S23)<=Settings!$B$10,"OK",IF(S23>0,"Sell ","Buy ")&TEXT(ABS(S23)*$B$5,"#,##0")&" €"))
G24: =IF(A24="","",SUMIFS(Transactions!$D$6:$D$505,Transactions!$C$6:$C$505,A24,Transactions!$B$6:$B$505,"Buy")-SUMIFS(Transactions!$D$6:$D$505,Transactions!$C$6:$C$505,A24,Transactions!$B$6:$B$505,"Sell")) | H24: =IF(A24="","",IFERROR((SUMIFS(Transactions!$I$6:$I$505,Transactions!$C$6:$C$505,A24,Transactions!$B$6:$B$505,"Buy")+SUMIFS(Transactions!$H$6:$H$505,Transactions!$C$6:$C$505,A24,Transactions!$B$6:$B$505,"Buy"))/SUMIFS(Transactions!$D$6:$D$505,Transactions!$C$6:$C$505,A24,Transactions!$B$6:$B$505,"Buy"),0)) | K24: =IF(A24="","",IFERROR(G24*I24*IF(EXACT(F24,"GBp"),0.01,1)/J24,0)) | L24: =IF(A24="","",IFERROR(K24/$B$5,0)) | M24: =IF(A24="","",G24*H24) | N24: =IF(A24="","",K24-M24) | O24: =IF(A24="","",IFERROR(N24/M24,0)) | S24: =IF(A24="","",L24-R24) | T24: =IF(A24="","",IF(ABS(S24)<=Settings!$B$10,"OK",IF(S24>0,"Sell ","Buy ")&TEXT(ABS(S24)*$B$5,"#,##0")&" €"))
... G47: =IF(A47="","",SUMIFS(Transactions!$D$6:$D$505,Transactions!$C$6:$C$505,A47,Transactions!$B$6:$B$505,"Buy")-SUMIFS(Transactions!$D$6:$D$505,Transactions!$C$6:$C$505,A47,Transactions!$B$6:$B$505,"Sell")) | H47: =IF(A47="","",IFERROR((SUMIFS(Transactions!$I$6:$I$505,Transactions!$C$6:$C$505,A47,Transactions!$B$6:$B$505,"Buy")+SUMIFS(Transactions!$H$6:$H$505,Transactions!$C$6:$C$505,A47,Transactions!$B$6:$B$505,"Buy"))/SUMIFS(Transactions!$D$6:$D$505,Transactions!$C$6:$C$505,A47,Transactions!$B$6:$B$505,"Buy"),0)) | K47: =IF(A47="","",IFERROR(G47*I47*IF(EXACT(F47,"GBp"),0.01,1)/J47,0)) | L47: =IF(A47="","",IFERROR(K47/$B$5,0)) | M47: =IF(A47="","",G47*H47) | N47: =IF(A47="","",K47-M47) | O47: =IF(A47="","",IFERROR(N47/M47,0)) | S47: =IF(A47="","",L47-R47) | T47: =IF(A47="","",IF(ABS(S47)<=Settings!$B$10,"OK",IF(S47>0,"Sell ","Buy ")&TEXT(ABS(S47)*$B$5,"#,##0")&" €"))
A48: Total | K48: =SUM(K8:K47) | L48: =SUM(L8:L47) | M48: =SUM(M8:M47) | N48: =SUM(N8:N47) | O48: =IFERROR(N48/M48,0) | R48: =SUM(R8:R47)
A49: Cash | K49: =B4 | L49: =IFERROR(B4/B5,0)

Sheet Transactions
A1: Transactions
A2: One row per event. Buy/Sell amounts are computed from quantity × price ÷ FX. For deposits, withdrawals, dividends and fees type the EUR amount in column J.
A5: Date | B5: Type | C5: Ticker | D5: Quantity | E5: Price (quote ccy) | F5: Quote currency | G5: FX (ccy per 1 EUR) | H5: Fees (EUR) | I5: Gross amount (EUR) | J5: Cash amount (EUR) | K5: Cash impact (EUR) | L5: Comment
A6: 45688 | B6: Deposit | F6: EUR | H6: 0 | I6: =IF(OR(B6="Buy",B6="Sell"),D6*E6*IF(EXACT(F6,"GBp"),0.01,1)/IF(G6="",1,G6),"") | J6: 10000 | K6: =IF(B6="","",IF(B6="Deposit",J6,IF(B6="Withdrawal",-J6,IF(B6="Buy",-(I6+H6),IF(B6="Sell",I6-H6,IF(B6="Dividend",J6,IF(B6="Fee",-J6,0))))))) | L6: Initial deposit
A7: 45691 | B7: Buy | C7: IWDA LN Equity | D7: 35 | E7: 101.2 | F7: USD | G7: 1.036 | H7: 3 | I7: =IF(OR(B7="Buy",B7="Sell"),D7*E7*IF(EXACT(F7,"GBp"),0.01,1)/IF(G7="",1,G7),"") | K7: =IF(B7="","",IF(B7="Deposit",J7,IF(B7="Withdrawal",-J7,IF(B7="Buy",-(I7+H7),IF(B7="Sell",I7-H7,IF(B7="Dividend",J7,IF(B7="Fee",-J7,0))))))) | L7: Value sleeve
A8: 45691 | B8: Buy | C8: EXS1 GY Equity | D8: 9 | E8: 182.5 | F8: EUR | G8: 1 | H8: 3 | I8: =IF(OR(B8="Buy",B8="Sell"),D8*E8*IF(EXACT(F8,"GBp"),0.01,1)/IF(G8="",1,G8),"") | K8: =IF(B8="","",IF(B8="Deposit",J8,IF(B8="Withdrawal",-J8,IF(B8="Buy",-(I8+H8),IF(B8="Sell",I8-H8,IF(B8="Dividend",J8,IF(B8="Fee",-J8,0))))))) | L8: Value sleeve
A9: 45691 | B9: Buy | C9: SGLN LN Equity | D9: 18 | E9: 4620 | F9: GBp | G9: 0.832 | H9: 3 | I9: =IF(OR(B9="Buy",B9="Sell"),D9*E9*IF(EXACT(F9,"GBp"),0.01,1)/IF(G9="",1,G9),"") | K9: =IF(B9="","",IF(B9="Deposit",J9,IF(B9="Withdrawal",-J9,IF(B9="Buy",-(I9+H9),IF(B9="Sell",I9-H9,IF(B9="Dividend",J9,IF(B9="Fee",-J9,0))))))) | L9: Trend signal: gold long
A10: 45691 | B10: Buy | C10: XEON GY Equity | D10: 12 | E10: 144.1 | F10: EUR | G10: 1 | H10: 2 | I10: =IF(OR(B10="Buy",B10="Sell"),D10*E10*IF(EXACT(F10,"GBp"),0.01,1)/IF(G10="",1,G10),"") | K10: =IF(B10="","",IF(B10="Deposit",J10,IF(B10="Withdrawal",-J10,IF(B10="Buy",-(I10+H10),IF(B10="Sell",I10-H10,IF(B10="Dividend",J10,IF(B10="Fee",-J10,0))))))) | L10: Cash buffer
A11: 45869 | B11: Deposit | F11: EUR | H11: 0 | I11: =IF(OR(B11="Buy",B11="Sell"),D11*E11*IF(EXACT(F11,"GBp"),0.01,1)/IF(G11="",1,G11),"") | J11: 2000 | K11: =IF(B11="","",IF(B11="Deposit",J11,IF(B11="Withdrawal",-J11,IF(B11="Buy",-(I11+H11),IF(B11="Sell",I11-H11,IF(B11="Dividend",J11,IF(B11="Fee",-J11,0))))))) | L11: Monthly savings
A12: 45870 | B12: Buy | C12: IBTM LN Equity | D12: 9 | E12: 160.4 | F12: USD | G12: 1.142 | H12: 3 | I12: =IF(OR(B12="Buy",B12="Sell"),D12*E12*IF(EXACT(F12,"GBp"),0.01,1)/IF(G12="",1,G12),"") | K12: =IF(B12="","",IF(B12="Deposit",J12,IF(B12="Withdrawal",-J12,IF(B12="Buy",-(I12+H12),IF(B12="Sell",I12-H12,IF(B12="Dividend",J12,IF(B12="Fee",-J12,0))))))) | L12: Trend signal: Treasuries long
A13: 45870 | B13: Buy | C13: IWDA LN Equity | D13: 4 | E13: 108.9 | F13: USD | G13: 1.142 | H13: 3 | I13: =IF(OR(B13="Buy",B13="Sell"),D13*E13*IF(EXACT(F13,"GBp"),0.01,1)/IF(G13="",1,G13),"") | K13: =IF(B13="","",IF(B13="Deposit",J13,IF(B13="Withdrawal",-J13,IF(B13="Buy",-(I13+H13),IF(B13="Sell",I13-H13,IF(B13="Dividend",J13,IF(B13="Fee",-J13,0))))))) | L13: Rebalance to target
A14: 46083 | B14: Sell | C14: IBTM LN Equity | D14: 3 | E14: 164 | F14: USD | G14: 1.118 | H14: 3 | I14: =IF(OR(B14="Buy",B14="Sell"),D14*E14*IF(EXACT(F14,"GBp"),0.01,1)/IF(G14="",1,G14),"") | K14: =IF(B14="","",IF(B14="Deposit",J14,IF(B14="Withdrawal",-J14,IF(B14="Buy",-(I14+H14),IF(B14="Sell",I14-H14,IF(B14="Dividend",J14,IF(B14="Fee",-J14,0))))))) | L14: Trend signal weakened
A15: 46112 | B15: Fee | F15: EUR | H15: 0 | I15: =IF(OR(B15="Buy",B15="Sell"),D15*E15*IF(EXACT(F15,"GBp"),0.01,1)/IF(G15="",1,G15),"") | J15: 5 | K15: =IF(B15="","",IF(B15="Deposit",J15,IF(B15="Withdrawal",-J15,IF(B15="Buy",-(I15+H15),IF(B15="Sell",I15-H15,IF(B15="Dividend",J15,IF(B15="Fee",-J15,0))))))) | L15: Platform fee
I16: =IF(OR(B16="Buy",B16="Sell"),D16*E16*IF(EXACT(F16,"GBp"),0.01,1)/IF(G16="",1,G16),"") | K16: =IF(B16="","",IF(B16="Deposit",J16,IF(B16="Withdrawal",-J16,IF(B16="Buy",-(I16+H16),IF(B16="Sell",I16-H16,IF(B16="Dividend",J16,IF(B16="Fee",-J16,0)))))))
I17: =IF(OR(B17="Buy",B17="Sell"),D17*E17*IF(EXACT(F17,"GBp"),0.01,1)/IF(G17="",1,G17),"") | K17: =IF(B17="","",IF(B17="Deposit",J17,IF(B17="Withdrawal",-J17,IF(B17="Buy",-(I17+H17),IF(B17="Sell",I17-H17,IF(B17="Dividend",J17,IF(B17="Fee",-J17,0)))))))
I18: =IF(OR(B18="Buy",B18="Sell"),D18*E18*IF(EXACT(F18,"GBp"),0.01,1)/IF(G18="",1,G18),"") | K18: =IF(B18="","",IF(B18="Deposit",J18,IF(B18="Withdrawal",-J18,IF(B18="Buy",-(I18+H18),IF(B18="Sell",I18-H18,IF(B18="Dividend",J18,IF(B18="Fee",-J18,0)))))))
I19: =IF(OR(B19="Buy",B19="Sell"),D19*E19*IF(EXACT(F19,"GBp"),0.01,1)/IF(G19="",1,G19),"") | K19: =IF(B19="","",IF(B19="Deposit",J19,IF(B19="Withdrawal",-J19,IF(B19="Buy",-(I19+H19),IF(B19="Sell",I19-H19,IF(B19="Dividend",J19,IF(B19="Fee",-J19,0)))))))
I20: =IF(OR(B20="Buy",B20="Sell"),D20*E20*IF(EXACT(F20,"GBp"),0.01,1)/IF(G20="",1,G20),"") | K20: =IF(B20="","",IF(B20="Deposit",J20,IF(B20="Withdrawal",-J20,IF(B20="Buy",-(I20+H20),IF(B20="Sell",I20-H20,IF(B20="Dividend",J20,IF(B20="Fee",-J20,0)))))))
I21: =IF(OR(B21="Buy",B21="Sell"),D21*E21*IF(EXACT(F21,"GBp"),0.01,1)/IF(G21="",1,G21),"") | K21: =IF(B21="","",IF(B21="Deposit",J21,IF(B21="Withdrawal",-J21,IF(B21="Buy",-(I21+H21),IF(B21="Sell",I21-H21,IF(B21="Dividend",J21,IF(B21="Fee",-J21,0)))))))
I22: =IF(OR(B22="Buy",B22="Sell"),D22*E22*IF(EXACT(F22,"GBp"),0.01,1)/IF(G22="",1,G22),"") | K22: =IF(B22="","",IF(B22="Deposit",J22,IF(B22="Withdrawal",-J22,IF(B22="Buy",-(I22+H22),IF(B22="Sell",I22-H22,IF(B22="Dividend",J22,IF(B22="Fee",-J22,0)))))))
I23: =IF(OR(B23="Buy",B23="Sell"),D23*E23*IF(EXACT(F23,"GBp"),0.01,1)/IF(G23="",1,G23),"") | K23: =IF(B23="","",IF(B23="Deposit",J23,IF(B23="Withdrawal",-J23,IF(B23="Buy",-(I23+H23),IF(B23="Sell",I23-H23,IF(B23="Dividend",J23,IF(B23="Fee",-J23,0)))))))
I24: =IF(OR(B24="Buy",B24="Sell"),D24*E24*IF(EXACT(F24,"GBp"),0.01,1)/IF(G24="",1,G24),"") | K24: =IF(B24="","",IF(B24="Deposit",J24,IF(B24="Withdrawal",-J24,IF(B24="Buy",-(I24+H24),IF(B24="Sell",I24-H24,IF(B24="Dividend",J24,IF(B24="Fee",-J24,0)))))))
I25: =IF(OR(B25="Buy",B25="Sell"),D25*E25*IF(EXACT(F25,"GBp"),0.01,1)/IF(G25="",1,G25),"") | K25: =IF(B25="","",IF(B25="Deposit",J25,IF(B25="Withdrawal",-J25,IF(B25="Buy",-(I25+H25),IF(B25="Sell",I25-H25,IF(B25="Dividend",J25,IF(B25="Fee",-J25,0)))))))
I26: =IF(OR(B26="Buy",B26="Sell"),D26*E26*IF(EXACT(F26,"GBp"),0.01,1)/IF(G26="",1,G26),"") | K26: =IF(B26="","",IF(B26="Deposit",J26,IF(B26="Withdrawal",-J26,IF(B26="Buy",-(I26+H26),IF(B26="Sell",I26-H26,IF(B26="Dividend",J26,IF(B26="Fee",-J26,0)))))))
I27: =IF(OR(B27="Buy",B27="Sell"),D27*E27*IF(EXACT(F27,"GBp"),0.01,1)/IF(G27="",1,G27),"") | K27: =IF(B27="","",IF(B27="Deposit",J27,IF(B27="Withdrawal",-J27,IF(B27="Buy",-(I27+H27),IF(B27="Sell",I27-H27,IF(B27="Dividend",J27,IF(B27="Fee",-J27,0)))))))
... I505: =IF(OR(B505="Buy",B505="Sell"),D505*E505*IF(EXACT(F505,"GBp"),0.01,1)/IF(G505="",1,G505),"") | K505: =IF(B505="","",IF(B505="Deposit",J505,IF(B505="Withdrawal",-J505,IF(B505="Buy",-(I505+H505),IF(B505="Sell",I505-H505,IF(B505="Dividend",J505,IF(B505="Fee",-J505,0)))))))

Sheet History
A1: History
A2: One row per month end. Type the date and total value (and the benchmark level in column E).
A5: Month end | B5: Portfolio value (EUR) | C5: Net external flows (EUR) | D5: Portfolio return | E5: Benchmark level | F5: Benchmark return | G5: Risk-free (monthly) | H5: Excess return | I5: Benchmark excess | J5: Active return | K5: NAV portfolio (base 100) | L5: NAV benchmark (base 100) | M5: Drawdown | N5: Benchmark drawdown | O5: Downside² (helper) | P5: Year (helper) | Q5: ln(1+r) (helper) | R5: Comment
A6: 45688 | B6: 10000 | C6: =IF(A6="","",SUMIFS(Transactions!$J$6:$J$505,Transactions!$B$6:$B$505,"Deposit",Transactions!$A$6:$A$505,">"&0,Transactions!$A$6:$A$505,"<="&A6)-SUMIFS(Transactions!$J$6:$J$505,Transactions!$B$6:$B$505,"Withdrawal",Transactions!$A$6:$A$505,">"&0,Transactions!$A$6:$A$505,"<="&A6)) | D6: ="" | E6: 412 | F6: ="" | G6: =IF(A6="","",Settings!$B$8/12) | H6: =IF(D6="","",D6-G6) | I6: =IF(F6="","",F6-G6) | J6: =IF(OR(D6="",F6=""),"",D6-F6) | K6: =IF(OR(A6="",B6=""),"",100) | L6: =IF(E6="","",100) | M6: =IF(K6="","",K6/MAX(K$6:K6)-1) | N6: =IF(L6="","",L6/MAX(L$6:L6)-1) | O6: =IF(H6="","",MIN(H6,0)^2) | P6: =IF(A6="","",YEAR(A6)) | Q6: =IF(D6="","",LN(1+D6)) | R6: Example — replace
A7: 45716 | B7: 10074.68 | C7: =IF(A7="","",SUMIFS(Transactions!$J$6:$J$505,Transactions!$B$6:$B$505,"Deposit",Transactions!$A$6:$A$505,">"&A6,Transactions!$A$6:$A$505,"<="&A7)-SUMIFS(Transactions!$J$6:$J$505,Transactions!$B$6:$B$505,"Withdrawal",Transactions!$A$6:$A$505,">"&A6,Transactions!$A$6:$A$505,"<="&A7)) | D7: =IF(OR(A7="",B7=""),"",IF(B6="","",(B7-B6-C7)/(B6+0.5*C7))) | E7: 411.61 | F7: =IF(OR(E7="",E6=""),"",E7/E6-1) | G7: =IF(A7="","",Settings!$B$8/12) | H7: =IF(D7="","",D7-G7) | I7: =IF(F7="","",F7-G7) | J7: =IF(OR(D7="",F7=""),"",D7-F7) | K7: =IF(OR(A7="",B7=""),"",IF(D7="",K6,K6*(1+D7))) | L7: =IF(E7="","",IF(F7="",L6,L6*(1+F7))) | M7: =IF(K7="","",K7/MAX(K$6:K7)-1) | N7: =IF(L7="","",L7/MAX(L$6:L7)-1) | O7: =IF(H7="","",MIN(H7,0)^2) | P7: =IF(A7="","",YEAR(A7)) | Q7: =IF(D7="","",LN(1+D7)) | R7: Example — replace
A8: 45747 | B8: 10057.35 | C8: =IF(A8="","",SUMIFS(Transactions!$J$6:$J$505,Transactions!$B$6:$B$505,"Deposit",Transactions!$A$6:$A$505,">"&A7,Transactions!$A$6:$A$505,"<="&A8)-SUMIFS(Transactions!$J$6:$J$505,Transactions!$B$6:$B$505,"Withdrawal",Transactions!$A$6:$A$505,">"&A7,Transactions!$A$6:$A$505,"<="&A8)) | D8: =IF(OR(A8="",B8=""),"",IF(B7="","",(B8-B7-C8)/(B7+0.5*C8))) | E8: 411.64 | F8: =IF(OR(E8="",E7=""),"",E8/E7-1) | G8: =IF(A8="","",Settings!$B$8/12) | H8: =IF(D8="","",D8-G8) | I8: =IF(F8="","",F8-G8) | J8: =IF(OR(D8="",F8=""),"",D8-F8) | K8: =IF(OR(A8="",B8=""),"",IF(D8="",K7,K7*(1+D8))) | L8: =IF(E8="","",IF(F8="",L7,L7*(1+F8))) | M8: =IF(K8="","",K8/MAX(K$6:K8)-1) | N8: =IF(L8="","",L8/MAX(L$6:L8)-1) | O8: =IF(H8="","",MIN(H8,0)^2) | P8: =IF(A8="","",YEAR(A8)) | Q8: =IF(D8="","",LN(1+D8)) | R8: Example — replace
A9: 45777 | B9: 9878.88 | C9: =IF(A9="","",SUMIFS(Transactions!$J$6:$J$505,Transactions!$B$6:$B$505,"Deposit",Transactions!$A$6:$A$505,">"&A8,Transactions!$A$6:$A$505,"<="&A9)-SUMIFS(Transactions!$J$6:$J$505,Transactions!$B$6:$B$505,"Withdrawal",Transactions!$A$6:$A$505,">"&A8,Transactions!$A$6:$A$505,"<="&A9)) | D9: =IF(OR(A9="",B9=""),"",IF(B8="","",(B9-B8-C9)/(B8+0.5*C9))) | E9: 401.54 | F9: =IF(OR(E9="",E8=""),"",E9/E8-1) | G9: =IF(A9="","",Settings!$B$8/12) | H9: =IF(D9="","",D9-G9) | I9: =IF(F9="","",F9-G9) | J9: =IF(OR(D9="",F9=""),"",D9-F9) | K9: =IF(OR(A9="",B9=""),"",IF(D9="",K8,K8*(1+D9))) | L9: =IF(E9="","",IF(F9="",L8,L8*(1+F9))) | M9: =IF(K9="","",K9/MAX(K$6:K9)-1) | N9: =IF(L9="","",L9/MAX(L$6:L9)-1) | O9: =IF(H9="","",MIN(H9,0)^2) | P9: =IF(A9="","",YEAR(A9)) | Q9: =IF(D9="","",LN(1+D9)) | R9: Example — replace
A10: 45808 | B10: 10273.36 | C10: =IF(A10="","",SUMIFS(Transactions!$J$6:$J$505,Transactions!$B$6:$B$505,"Deposit",Transactions!$A$6:$A$505,">"&A9,Transactions!$A$6:$A$505,"<="&A10)-SUMIFS(Transactions!$J$6:$J$505,Transactions!$B$6:$B$505,"Withdrawal",Transactions!$A$6:$A$505,">"&A9,Transactions!$A$6:$A$505,"<="&A10)) | D10: =IF(OR(A10="",B10=""),"",IF(B9="","",(B10-B9-C10)/(B9+0.5*C10))) | E10: 420.37 | F10: =IF(OR(E10="",E9=""),"",E10/E9-1) | G10: =IF(A10="","",Settings!$B$8/12) | H10: =IF(D10="","",D10-G10) | I10: =IF(F10="","",F10-G10) | J10: =IF(OR(D10="",F10=""),"",D10-F10) | K10: =IF(OR(A10="",B10=""),"",IF(D10="",K9,K9*(1+D10))) | L10: =IF(E10="","",IF(F10="",L9,L9*(1+F10))) | M10: =IF(K10="","",K10/MAX(K$6:K10)-1) | N10: =IF(L10="","",L10/MAX(L$6:L10)-1) | O10: =IF(H10="","",MIN(H10,0)^2) | P10: =IF(A10="","",YEAR(A10)) | Q10: =IF(D10="","",LN(1+D10)) | R10: Example — replace
A11: 45838 | B11: 10643.11 | C11: =IF(A11="","",SUMIFS(Transactions!$J$6:$J$505,Transactions!$B$6:$B$505,"Deposit",Transactions!$A$6:$A$505,">"&A10,Transactions!$A$6:$A$505,"<="&A11)-SUMIFS(Transactions!$J$6:$J$505,Transactions!$B$6:$B$505,"Withdrawal",Transactions!$A$6:$A$505,">"&A10,Transactions!$A$6:$A$505,"<="&A11)) | D11: =IF(OR(A11="",B11=""),"",IF(B10="","",(B11-B10-C11)/(B10+0.5*C11))) | E11: 438.99 | F11: =IF(OR(E11="",E10=""),"",E11/E10-1) | G11: =IF(A11="","",Settings!$B$8/12) | H11: =IF(D11="","",D11-G11) | I11: =IF(F11="","",F11-G11) | J11: =IF(OR(D11="",F11=""),"",D11-F11) | K11: =IF(OR(A11="",B11=""),"",IF(D11="",K10,K10*(1+D11))) | L11: =IF(E11="","",IF(F11="",L10,L10*(1+F11))) | M11: =IF(K11="","",K11/MAX(K$6:K11)-1) | N11: =IF(L11="","",L11/MAX(L$6:L11)-1) | O11: =IF(H11="","",MIN(H11,0)^2) | P11: =IF(A11="","",YEAR(A11)) | Q11: =IF(D11="","",LN(1+D11)) | R11: Example — replace
A12: 45869 | B12: 12850.6 | C12: =IF(A12="","",SUMIFS(Transactions!$J$6:$J$505,Transactions!$B$6:$B$505,"Deposit",Transactions!$A$6:$A$505,">"&A11,Transactions!$A$6:$A$505,"<="&A12)-SUMIFS(Transactions!$J$6:$J$505,Transactions!$B$6:$B$505,"Withdrawal",Transactions!$A$6:$A$505,">"&A11,Transactions!$A$6:$A$505,"<="&A12)) | D12: =IF(OR(A12="",B12=""),"",IF(B11="","",(B12-B11-C12)/(B11+0.5*C12))) | E12: 448.57 | F12: =IF(OR(E12="",E11=""),"",E12/E11-1) | G12: =IF(A12="","",Settings!$B$8/12) | H12: =IF(D12="","",D12-G12) | I12: =IF(F12="","",F12-G12) | J12: =IF(OR(D12="",F12=""),"",D12-F12) | K12: =IF(OR(A12="",B12=""),"",IF(D12="",K11,K11*(1+D12))) | L12: =IF(E12="","",IF(F12="",L11,L11*(1+F12))) | M12: =IF(K12="","",K12/MAX(K$6:K12)-1) | N12: =IF(L12="","",L12/MAX(L$6:L12)-1) | O12: =IF(H12="","",MIN(H12,0)^2) | P12: =IF(A12="","",YEAR(A12)) | Q12: =IF(D12="","",LN(1+D12)) | R12: Example — replace
A13: 45900 | B13: 12555.61 | C13: =IF(A13="","",SUMIFS(Transactions!$J$6:$J$505,Transactions!$B$6:$B$505,"Deposit",Transactions!$A$6:$A$505,">"&A12,Transactions!$A$6:$A$505,"<="&A13)-SUMIFS(Transactions!$J$6:$J$505,Transactions!$B$6:$B$505,"Withdrawal",Transactions!$A$6:$A$505,">"&A12,Transactions!$A$6:$A$505,"<="&A13)) | D13: =IF(OR(A13="",B13=""),"",IF(B12="","",(B13-B12-C13)/(B12+0.5*C13))) | E13: 426 | F13: =IF(OR(E13="",E12=""),"",E13/E12-1) | G13: =IF(A13="","",Settings!$B$8/12) | H13: =IF(D13="","",D13-G13) | I13: =IF(F13="","",F13-G13) | J13: =IF(OR(D13="",F13=""),"",D13-F13) | K13: =IF(OR(A13="",B13=""),"",IF(D13="",K12,K12*(1+D13))) | L13: =IF(E13="","",IF(F13="",L12,L12*(1+F13))) | M13: =IF(K13="","",K13/MAX(K$6:K13)-1) | N13: =IF(L13="","",L13/MAX(L$6:L13)-1) | O13: =IF(H13="","",MIN(H13,0)^2) | P13: =IF(A13="","",YEAR(A13)) | Q13: =IF(D13="","",LN(1+D13)) | R13: Example — replace
A14: 45930 | B14: 12881.96 | C14: =IF(A14="","",SUMIFS(Transactions!$J$6:$J$505,Transactions!$B$6:$B$505,"Deposit",Transactions!$A$6:$A$505,">"&A13,Transactions!$A$6:$A$505,"<="&A14)-SUMIFS(Transactions!$J$6:$J$505,Transactions!$B$6:$B$505,"Withdrawal",Transactions!$A$6:$A$505,">"&A13,Transactions!$A$6:$A$505,"<="&A14)) | D14: =IF(OR(A14="",B14=""),"",IF(B13="","",(B14-B13-C14)/(B13+0.5*C14))) | E14: 436.96 | F14: =IF(OR(E14="",E13=""),"",E14/E13-1) | G14: =IF(A14="","",Settings!$B$8/12) | H14: =IF(D14="","",D14-G14) | I14: =IF(F14="","",F14-G14) | J14: =IF(OR(D14="",F14=""),"",D14-F14) | K14: =IF(OR(A14="",B14=""),"",IF(D14="",K13,K13*(1+D14))) | L14: =IF(E14="","",IF(F14="",L13,L13*(1+F14))) | M14: =IF(K14="","",K14/MAX(K$6:K14)-1) | N14: =IF(L14="","",L14/MAX(L$6:L14)-1) | O14: =IF(H14="","",MIN(H14,0)^2) | P14: =IF(A14="","",YEAR(A14)) | Q14: =IF(D14="","",LN(1+D14)) | R14: Example — replace
A15: 45961 | B15: 12176.48 | C15: =IF(A15="","",SUMIFS(Transactions!$J$6:$J$505,Transactions!$B$6:$B$505,"Deposit",Transactions!$A$6:$A$505,">"&A14,Transactions!$A$6:$A$505,"<="&A15)-SUMIFS(Transactions!$J$6:$J$505,Transactions!$B$6:$B$505,"Withdrawal",Transactions!$A$6:$A$505,">"&A14,Transactions!$A$6:$A$505,"<="&A15)) | D15: =IF(OR(A15="",B15=""),"",IF(B14="","",(B15-B14-C15)/(B14+0.5*C15))) | E15: 414.59 | F15: =IF(OR(E15="",E14=""),"",E15/E14-1) | G15: =IF(A15="","",Settings!$B$8/12) | H15: =IF(D15="","",D15-G15) | I15: =IF(F15="","",F15-G15) | J15: =IF(OR(D15="",F15=""),"",D15-F15) | K15: =IF(OR(A15="",B15=""),"",IF(D15="",K14,K14*(1+D15))) | L15: =IF(E15="","",IF(F15="",L14,L14*(1+F15))) | M15: =IF(K15="","",K15/MAX(K$6:K15)-1) | N15: =IF(L15="","",L15/MAX(L$6:L15)-1) | O15: =IF(H15="","",MIN(H15,0)^2) | P15: =IF(A15="","",YEAR(A15)) | Q15: =IF(D15="","",LN(1+D15)) | R15: Example — replace
A16: 45991 | B16: 11935.21 | C16: =IF(A16="","",SUMIFS(Transactions!$J$6:$J$505,Transactions!$B$6:$B$505,"Deposit",Transactions!$A$6:$A$505,">"&A15,Transactions!$A$6:$A$505,"<="&A16)-SUMIFS(Transactions!$J$6:$J$505,Transactions!$B$6:$B$505,"Withdrawal",Transactions!$A$6:$A$505,">"&A15,Transactions!$A$6:$A$505,"<="&A16)) | D16: =IF(OR(A16="",B16=""),"",IF(B15="","",(B16-B15-C16)/(B15+0.5*C16))) | E16: 405 | F16: =IF(OR(E16="",E15=""),"",E16/E15-1) | G16: =IF(A16="","",Settings!$B$8/12) | H16: =IF(D16="","",D16-G16) | I16: =IF(F16="","",F16-G16) | J16: =IF(OR(D16="",F16=""),"",D16-F16) | K16: =IF(OR(A16="",B16=""),"",IF(D16="",K15,K15*(1+D16))) | L16: =IF(E16="","",IF(F16="",L15,L15*(1+F16))) | M16: =IF(K16="","",K16/MAX(K$6:K16)-1) | N16: =IF(L16="","",L16/MAX(L$6:L16)-1) | O16: =IF(H16="","",MIN(H16,0)^2) | P16: =IF(A16="","",YEAR(A16)) | Q16: =IF(D16="","",LN(1+D16)) | R16: Example — replace
A17: 46022 | B17: 12108.66 | C17: =IF(A17="","",SUMIFS(Transactions!$J$6:$J$505,Transactions!$B$6:$B$505,"Deposit",Transactions!$A$6:$A$505,">"&A16,Transactions!$A$6:$A$505,"<="&A17)-SUMIFS(Transactions!$J$6:$J$505,Transactions!$B$6:$B$505,"Withdrawal",Transactions!$A$6:$A$505,">"&A16,Transactions!$A$6:$A$505,"<="&A17)) | D17: =IF(OR(A17="",B17=""),"",IF(B16="","",(B17-B16-C17)/(B16+0.5*C17))) | E17: 412.57 | F17: =IF(OR(E17="",E16=""),"",E17/E16-1) | G17: =IF(A17="","",Settings!$B$8/12) | H17: =IF(D17="","",D17-G17) | I17: =IF(F17="","",F17-G17) | J17: =IF(OR(D17="",F17=""),"",D17-F17) | K17: =IF(OR(A17="",B17=""),"",IF(D17="",K16,K16*(1+D17))) | L17: =IF(E17="","",IF(F17="",L16,L16*(1+F17))) | M17: =IF(K17="","",K17/MAX(K$6:K17)-1) | N17: =IF(L17="","",L17/MAX(L$6:L17)-1) | O17: =IF(H17="","",MIN(H17,0)^2) | P17: =IF(A17="","",YEAR(A17)) | Q17: =IF(D17="","",LN(1+D17)) | R17: Example — replace
A18: 46053 | B18: 12261.92 | C18: =IF(A18="","",SUMIFS(Transactions!$J$6:$J$505,Transactions!$B$6:$B$505,"Deposit",Transactions!$A$6:$A$505,">"&A17,Transactions!$A$6:$A$505,"<="&A18)-SUMIFS(Transactions!$J$6:$J$505,Transactions!$B$6:$B$505,"Withdrawal",Transactions!$A$6:$A$505,">"&A17,Transactions!$A$6:$A$505,"<="&A18)) | D18: =IF(OR(A18="",B18=""),"",IF(B17="","",(B18-B17-C18)/(B17+0.5*C18))) | E18: 423.39 | F18: =IF(OR(E18="",E17=""),"",E18/E17-1) | G18: =IF(A18="","",Settings!$B$8/12) | H18: =IF(D18="","",D18-G18) | I18: =IF(F18="","",F18-G18) | J18: =IF(OR(D18="",F18=""),"",D18-F18) | K18: =IF(OR(A18="",B18=""),"",IF(D18="",K17,K17*(1+D18))) | L18: =IF(E18="","",IF(F18="",L17,L17*(1+F18))) | M18: =IF(K18="","",K18/MAX(K$6:K18)-1) | N18: =IF(L18="","",L18/MAX(L$6:L18)-1) | O18: =IF(H18="","",MIN(H18,0)^2) | P18: =IF(A18="","",YEAR(A18)) | Q18: =IF(D18="","",LN(1+D18)) | R18: Example — replace
... A26: 46295 | B26: 12679.23 | C26: =IF(A26="","",SUMIFS(Transactions!$J$6:$J$505,Transactions!$B$6:$B$505,"Deposit",Transactions!$A$6:$A$505,">"&A25,Transactions!$A$6:$A$505,"<="&A26)-SUMIFS(Transactions!$J$6:$J$505,Transactions!$B$6:$B$505,"Withdrawal",Transactions!$A$6:$A$505,">"&A25,Transactions!$A$6:$A$505,"<="&A26)) | D26: =IF(OR(A26="",B26=""),"",IF(B25="","",(B26-B25-C26)/(B25+0.5*C26))) | E26: 433.82 | F26: =IF(OR(E26="",E25=""),"",E26/E25-1) | G26: =IF(A26="","",Settings!$B$8/12) | H26: =IF(D26="","",D26-G26) | I26: =IF(F26="","",F26-G26) | J26: =IF(OR(D26="",F26=""),"",D26-F26) | K26: =IF(OR(A26="",B26=""),"",IF(D26="",K25,K25*(1+D26))) | L26: =IF(E26="","",IF(F26="",L25,L25*(1+F26))) | M26: =IF(K26="","",K26/MAX(K$6:K26)-1) | N26: =IF(L26="","",L26/MAX(L$6:L26)-1) | O26: =IF(H26="","",MIN(H26,0)^2) | P26: =IF(A26="","",YEAR(A26)) | Q26: =IF(D26="","",LN(1+D26)) | R26: Example — replace
C27: =IF(A27="","",SUMIFS(Transactions!$J$6:$J$505,Transactions!$B$6:$B$505,"Deposit",Transactions!$A$6:$A$505,">"&A26,Transactions!$A$6:$A$505,"<="&A27)-SUMIFS(Transactions!$J$6:$J$505,Transactions!$B$6:$B$505,"Withdrawal",Transactions!$A$6:$A$505,">"&A26,Transactions!$A$6:$A$505,"<="&A27)) | D27: =IF(OR(A27="",B27=""),"",IF(B26="","",(B27-B26-C27)/(B26+0.5*C27))) | F27: =IF(OR(E27="",E26=""),"",E27/E26-1) | G27: =IF(A27="","",Settings!$B$8/12) | H27: =IF(D27="","",D27-G27) | I27: =IF(F27="","",F27-G27) | J27: =IF(OR(D27="",F27=""),"",D27-F27) | K27: =IF(OR(A27="",B27=""),"",IF(D27="",K26,K26*(1+D27))) | L27: =IF(E27="","",IF(F27="",L26,L26*(1+F27))) | M27: =IF(K27="","",K27/MAX(K$6:K27)-1) | N27: =IF(L27="","",L27/MAX(L$6:L27)-1) | O27: =IF(H27="","",MIN(H27,0)^2) | P27: =IF(A27="","",YEAR(A27)) | Q27: =IF(D27="","",LN(1+D27))
C28: =IF(A28="","",SUMIFS(Transactions!$J$6:$J$505,Transactions!$B$6:$B$505,"Deposit",Transactions!$A$6:$A$505,">"&A27,Transactions!$A$6:$A$505,"<="&A28)-SUMIFS(Transactions!$J$6:$J$505,Transactions!$B$6:$B$505,"Withdrawal",Transactions!$A$6:$A$505,">"&A27,Transactions!$A$6:$A$505,"<="&A28)) | D28: =IF(OR(A28="",B28=""),"",IF(B27="","",(B28-B27-C28)/(B27+0.5*C28))) | F28: =IF(OR(E28="",E27=""),"",E28/E27-1) | G28: =IF(A28="","",Settings!$B$8/12) | H28: =IF(D28="","",D28-G28) | I28: =IF(F28="","",F28-G28) | J28: =IF(OR(D28="",F28=""),"",D28-F28) | K28: =IF(OR(A28="",B28=""),"",IF(D28="",K27,K27*(1+D28))) | L28: =IF(E28="","",IF(F28="",L27,L27*(1+F28))) | M28: =IF(K28="","",K28/MAX(K$6:K28)-1) | N28: =IF(L28="","",L28/MAX(L$6:L28)-1) | O28: =IF(H28="","",MIN(H28,0)^2) | P28: =IF(A28="","",YEAR(A28)) | Q28: =IF(D28="","",LN(1+D28))
C29: =IF(A29="","",SUMIFS(Transactions!$J$6:$J$505,Transactions!$B$6:$B$505,"Deposit",Transactions!$A$6:$A$505,">"&A28,Transactions!$A$6:$A$505,"<="&A29)-SUMIFS(Transactions!$J$6:$J$505,Transactions!$B$6:$B$505,"Withdrawal",Transactions!$A$6:$A$505,">"&A28,Transactions!$A$6:$A$505,"<="&A29)) | D29: =IF(OR(A29="",B29=""),"",IF(B28="","",(B29-B28-C29)/(B28+0.5*C29))) | F29: =IF(OR(E29="",E28=""),"",E29/E28-1) | G29: =IF(A29="","",Settings!$B$8/12) | H29: =IF(D29="","",D29-G29) | I29: =IF(F29="","",F29-G29) | J29: =IF(OR(D29="",F29=""),"",D29-F29) | K29: =IF(OR(A29="",B29=""),"",IF(D29="",K28,K28*(1+D29))) | L29: =IF(E29="","",IF(F29="",L28,L28*(1+F29))) | M29: =IF(K29="","",K29/MAX(K$6:K29)-1) | N29: =IF(L29="","",L29/MAX(L$6:L29)-1) | O29: =IF(H29="","",MIN(H29,0)^2) | P29: =IF(A29="","",YEAR(A29)) | Q29: =IF(D29="","",LN(1+D29))
C30: =IF(A30="","",SUMIFS(Transactions!$J$6:$J$505,Transactions!$B$6:$B$505,"Deposit",Transactions!$A$6:$A$505,">"&A29,Transactions!$A$6:$A$505,"<="&A30)-SUMIFS(Transactions!$J$6:$J$505,Transactions!$B$6:$B$505,"Withdrawal",Transactions!$A$6:$A$505,">"&A29,Transactions!$A$6:$A$505,"<="&A30)) | D30: =IF(OR(A30="",B30=""),"",IF(B29="","",(B30-B29-C30)/(B29+0.5*C30))) | F30: =IF(OR(E30="",E29=""),"",E30/E29-1) | G30: =IF(A30="","",Settings!$B$8/12) | H30: =IF(D30="","",D30-G30) | I30: =IF(F30="","",F30-G30) | J30: =IF(OR(D30="",F30=""),"",D30-F30) | K30: =IF(OR(A30="",B30=""),"",IF(D30="",K29,K29*(1+D30))) | L30: =IF(E30="","",IF(F30="",L29,L29*(1+F30))) | M30: =IF(K30="","",K30/MAX(K$6:K30)-1) | N30: =IF(L30="","",L30/MAX(L$6:L30)-1) | O30: =IF(H30="","",MIN(H30,0)^2) | P30: =IF(A30="","",YEAR(A30)) | Q30: =IF(D30="","",LN(1+D30))
C31: =IF(A31="","",SUMIFS(Transactions!$J$6:$J$505,Transactions!$B$6:$B$505,"Deposit",Transactions!$A$6:$A$505,">"&A30,Transactions!$A$6:$A$505,"<="&A31)-SUMIFS(Transactions!$J$6:$J$505,Transactions!$B$6:$B$505,"Withdrawal",Transactions!$A$6:$A$505,">"&A30,Transactions!$A$6:$A$505,"<="&A31)) | D31: =IF(OR(A31="",B31=""),"",IF(B30="","",(B31-B30-C31)/(B30+0.5*C31))) | F31: =IF(OR(E31="",E30=""),"",E31/E30-1) | G31: =IF(A31="","",Settings!$B$8/12) | H31: =IF(D31="","",D31-G31) | I31: =IF(F31="","",F31-G31) | J31: =IF(OR(D31="",F31=""),"",D31-F31) | K31: =IF(OR(A31="",B31=""),"",IF(D31="",K30,K30*(1+D31))) | L31: =IF(E31="","",IF(F31="",L30,L30*(1+F31))) | M31: =IF(K31="","",K31/MAX(K$6:K31)-1) | N31: =IF(L31="","",L31/MAX(L$6:L31)-1) | O31: =IF(H31="","",MIN(H31,0)^2) | P31: =IF(A31="","",YEAR(A31)) | Q31: =IF(D31="","",LN(1+D31))
C32: =IF(A32="","",SUMIFS(Transactions!$J$6:$J$505,Transactions!$B$6:$B$505,"Deposit",Transactions!$A$6:$A$505,">"&A31,Transactions!$A$6:$A$505,"<="&A32)-SUMIFS(Transactions!$J$6:$J$505,Transactions!$B$6:$B$505,"Withdrawal",Transactions!$A$6:$A$505,">"&A31,Transactions!$A$6:$A$505,"<="&A32)) | D32: =IF(OR(A32="",B32=""),"",IF(B31="","",(B32-B31-C32)/(B31+0.5*C32))) | F32: =IF(OR(E32="",E31=""),"",E32/E31-1) | G32: =IF(A32="","",Settings!$B$8/12) | H32: =IF(D32="","",D32-G32) | I32: =IF(F32="","",F32-G32) | J32: =IF(OR(D32="",F32=""),"",D32-F32) | K32: =IF(OR(A32="",B32=""),"",IF(D32="",K31,K31*(1+D32))) | L32: =IF(E32="","",IF(F32="",L31,L31*(1+F32))) | M32: =IF(K32="","",K32/MAX(K$6:K32)-1) | N32: =IF(L32="","",L32/MAX(L$6:L32)-1) | O32: =IF(H32="","",MIN(H32,0)^2) | P32: =IF(A32="","",YEAR(A32)) | Q32: =IF(D32="","",LN(1+D32))
C33: =IF(A33="","",SUMIFS(Transactions!$J$6:$J$505,Transactions!$B$6:$B$505,"Deposit",Transactions!$A$6:$A$505,">"&A32,Transactions!$A$6:$A$505,"<="&A33)-SUMIFS(Transactions!$J$6:$J$505,Transactions!$B$6:$B$505,"Withdrawal",Transactions!$A$6:$A$505,">"&A32,Transactions!$A$6:$A$505,"<="&A33)) | D33: =IF(OR(A33="",B33=""),"",IF(B32="","",(B33-B32-C33)/(B32+0.5*C33))) | F33: =IF(OR(E33="",E32=""),"",E33/E32-1) | G33: =IF(A33="","",Settings!$B$8/12) | H33: =IF(D33="","",D33-G33) | I33: =IF(F33="","",F33-G33) | J33: =IF(OR(D33="",F33=""),"",D33-F33) | K33: =IF(OR(A33="",B33=""),"",IF(D33="",K32,K32*(1+D33))) | L33: =IF(E33="","",IF(F33="",L32,L32*(1+F33))) | M33: =IF(K33="","",K33/MAX(K$6:K33)-1) | N33: =IF(L33="","",L33/MAX(L$6:L33)-1) | O33: =IF(H33="","",MIN(H33,0)^2) | P33: =IF(A33="","",YEAR(A33)) | Q33: =IF(D33="","",LN(1+D33))
C34: =IF(A34="","",SUMIFS(Transactions!$J$6:$J$505,Transactions!$B$6:$B$505,"Deposit",Transactions!$A$6:$A$505,">"&A33,Transactions!$A$6:$A$505,"<="&A34)-SUMIFS(Transactions!$J$6:$J$505,Transactions!$B$6:$B$505,"Withdrawal",Transactions!$A$6:$A$505,">"&A33,Transactions!$A$6:$A$505,"<="&A34)) | D34: =IF(OR(A34="",B34=""),"",IF(B33="","",(B34-B33-C34)/(B33+0.5*C34))) | F34: =IF(OR(E34="",E33=""),"",E34/E33-1) | G34: =IF(A34="","",Settings!$B$8/12) | H34: =IF(D34="","",D34-G34) | I34: =IF(F34="","",F34-G34) | J34: =IF(OR(D34="",F34=""),"",D34-F34) | K34: =IF(OR(A34="",B34=""),"",IF(D34="",K33,K33*(1+D34))) | L34: =IF(E34="","",IF(F34="",L33,L33*(1+F34))) | M34: =IF(K34="","",K34/MAX(K$6:K34)-1) | N34: =IF(L34="","",L34/MAX(L$6:L34)-1) | O34: =IF(H34="","",MIN(H34,0)^2) | P34: =IF(A34="","",YEAR(A34)) | Q34: =IF(D34="","",LN(1+D34))
C35: =IF(A35="","",SUMIFS(Transactions!$J$6:$J$505,Transactions!$B$6:$B$505,"Deposit",Transactions!$A$6:$A$505,">"&A34,Transactions!$A$6:$A$505,"<="&A35)-SUMIFS(Transactions!$J$6:$J$505,Transactions!$B$6:$B$505,"Withdrawal",Transactions!$A$6:$A$505,">"&A34,Transactions!$A$6:$A$505,"<="&A35)) | D35: =IF(OR(A35="",B35=""),"",IF(B34="","",(B35-B34-C35)/(B34+0.5*C35))) | F35: =IF(OR(E35="",E34=""),"",E35/E34-1) | G35: =IF(A35="","",Settings!$B$8/12) | H35: =IF(D35="","",D35-G35) | I35: =IF(F35="","",F35-G35) | J35: =IF(OR(D35="",F35=""),"",D35-F35) | K35: =IF(OR(A35="",B35=""),"",IF(D35="",K34,K34*(1+D35))) | L35: =IF(E35="","",IF(F35="",L34,L34*(1+F35))) | M35: =IF(K35="","",K35/MAX(K$6:K35)-1) | N35: =IF(L35="","",L35/MAX(L$6:L35)-1) | O35: =IF(H35="","",MIN(H35,0)^2) | P35: =IF(A35="","",YEAR(A35)) | Q35: =IF(D35="","",LN(1+D35))
C36: =IF(A36="","",SUMIFS(Transactions!$J$6:$J$505,Transactions!$B$6:$B$505,"Deposit",Transactions!$A$6:$A$505,">"&A35,Transactions!$A$6:$A$505,"<="&A36)-SUMIFS(Transactions!$J$6:$J$505,Transactions!$B$6:$B$505,"Withdrawal",Transactions!$A$6:$A$505,">"&A35,Transactions!$A$6:$A$505,"<="&A36)) | D36: =IF(OR(A36="",B36=""),"",IF(B35="","",(B36-B35-C36)/(B35+0.5*C36))) | F36: =IF(OR(E36="",E35=""),"",E36/E35-1) | G36: =IF(A36="","",Settings!$B$8/12) | H36: =IF(D36="","",D36-G36) | I36: =IF(F36="","",F36-G36) | J36: =IF(OR(D36="",F36=""),"",D36-F36) | K36: =IF(OR(A36="",B36=""),"",IF(D36="",K35,K35*(1+D36))) | L36: =IF(E36="","",IF(F36="",L35,L35*(1+F36))) | M36: =IF(K36="","",K36/MAX(K$6:K36)-1) | N36: =IF(L36="","",L36/MAX(L$6:L36)-1) | O36: =IF(H36="","",MIN(H36,0)^2) | P36: =IF(A36="","",YEAR(A36)) | Q36: =IF(D36="","",LN(1+D36))
C37: =IF(A37="","",SUMIFS(Transactions!$J$6:$J$505,Transactions!$B$6:$B$505,"Deposit",Transactions!$A$6:$A$505,">"&A36,Transactions!$A$6:$A$505,"<="&A37)-SUMIFS(Transactions!$J$6:$J$505,Transactions!$B$6:$B$505,"Withdrawal",Transactions!$A$6:$A$505,">"&A36,Transactions!$A$6:$A$505,"<="&A37)) | D37: =IF(OR(A37="",B37=""),"",IF(B36="","",(B37-B36-C37)/(B36+0.5*C37))) | F37: =IF(OR(E37="",E36=""),"",E37/E36-1) | G37: =IF(A37="","",Settings!$B$8/12) | H37: =IF(D37="","",D37-G37) | I37: =IF(F37="","",F37-G37) | J37: =IF(OR(D37="",F37=""),"",D37-F37) | K37: =IF(OR(A37="",B37=""),"",IF(D37="",K36,K36*(1+D37))) | L37: =IF(E37="","",IF(F37="",L36,L36*(1+F37))) | M37: =IF(K37="","",K37/MAX(K$6:K37)-1) | N37: =IF(L37="","",L37/MAX(L$6:L37)-1) | O37: =IF(H37="","",MIN(H37,0)^2) | P37: =IF(A37="","",YEAR(A37)) | Q37: =IF(D37="","",LN(1+D37))
C38: =IF(A38="","",SUMIFS(Transactions!$J$6:$J$505,Transactions!$B$6:$B$505,"Deposit",Transactions!$A$6:$A$505,">"&A37,Transactions!$A$6:$A$505,"<="&A38)-SUMIFS(Transactions!$J$6:$J$505,Transactions!$B$6:$B$505,"Withdrawal",Transactions!$A$6:$A$505,">"&A37,Transactions!$A$6:$A$505,"<="&A38)) | D38: =IF(OR(A38="",B38=""),"",IF(B37="","",(B38-B37-C38)/(B37+0.5*C38))) | F38: =IF(OR(E38="",E37=""),"",E38/E37-1) | G38: =IF(A38="","",Settings!$B$8/12) | H38: =IF(D38="","",D38-G38) | I38: =IF(F38="","",F38-G38) | J38: =IF(OR(D38="",F38=""),"",D38-F38) | K38: =IF(OR(A38="",B38=""),"",IF(D38="",K37,K37*(1+D38))) | L38: =IF(E38="","",IF(F38="",L37,L37*(1+F38))) | M38: =IF(K38="","",K38/MAX(K$6:K38)-1) | N38: =IF(L38="","",L38/MAX(L$6:L38)-1) | O38: =IF(H38="","",MIN(H38,0)^2) | P38: =IF(A38="","",YEAR(A38)) | Q38: =IF(D38="","",LN(1+D38))
... C185: =IF(A185="","",SUMIFS(Transactions!$J$6:$J$505,Transactions!$B$6:$B$505,"Deposit",Transactions!$A$6:$A$505,">"&A184,Transactions!$A$6:$A$505,"<="&A185)-SUMIFS(Transactions!$J$6:$J$505,Transactions!$B$6:$B$505,"Withdrawal",Transactions!$A$6:$A$505,">"&A184,Transactions!$A$6:$A$505,"<="&A185)) | D185: =IF(OR(A185="",B185=""),"",IF(B184="","",(B185-B184-C185)/(B184+0.5*C185))) | F185: =IF(OR(E185="",E184=""),"",E185/E184-1) | G185: =IF(A185="","",Settings!$B$8/12) | H185: =IF(D185="","",D185-G185) | I185: =IF(F185="","",F185-G185) | J185: =IF(OR(D185="",F185=""),"",D185-F185) | K185: =IF(OR(A185="",B185=""),"",IF(D185="",K184,K184*(1+D185))) | L185: =IF(E185="","",IF(F185="",L184,L184*(1+F185))) | M185: =IF(K185="","",K185/MAX(K$6:K185)-1) | N185: =IF(L185="","",L185/MAX(L$6:L185)-1) | O185: =IF(H185="","",MIN(H185,0)^2) | P185: =IF(A185="","",YEAR(A185)) | Q185: =IF(D185="","",LN(1+D185))

Sheet Risk
A1: Risk & ratios
A2: Monthly data from History. Each figure is compared with the benchmark and explained in plain words.
A4: Metric | B4: Portfolio | C4: Benchmark | D4: Reading | E4: What it means
A5: Months of history | B5: =COUNT(History!$D$6:$D$185) | C5: =COUNT(History!$F$6:$F$185) | E5: Number of monthly returns used. Below 12 months, treat every ratio as indicative only.
A6: Total return (time-weighted) | B6: =IFERROR(LOOKUP(9.99E+307,History!$K$6:$K$185)/100-1,0) | C6: =IFERROR(LOOKUP(9.99E+307,History!$L$6:$L$185)/100-1,0) | E6: Growth of 100 invested at inception, excluding the effect of deposits and withdrawals.
A7: Annualised return | B7: =IFERROR((1+B6)^(12/B5)-1,0) | C7: =IFERROR((1+C6)^(12/C5)-1,0) | E7: Compound yearly growth rate over the history.
A8: Year-to-date return | B8: =IFERROR(EXP(SUMIFS(History!$Q$6:$Q$185,History!$P$6:$P$185,YEAR(LOOKUP(9.99E+307,History!$A$6:$A$185))))-1,0) | E8: Time-weighted return since 1 January of the current year.
A9: Annualised volatility | B9: =IFERROR(STDEV(History!$D$6:$D$185)*SQRT(12),0) | C9: =IFERROR(STDEV(History!$F$6:$F$185)*SQRT(12),0) | D9: =IF(B9>C9,"More volatile","Less volatile") | E9: Typical size of yearly fluctuations. Monthly standard deviation × √12.
A10: Sharpe ratio | B10: =IFERROR(AVERAGE(History!$H$6:$H$185)*12/(STDEV(History!$H$6:$H$185)*SQRT(12)),0) | C10: =IFERROR(AVERAGE(History!$I$6:$I$185)*12/(STDEV(History!$I$6:$I$185)*SQRT(12)),0) | D10: =IF(B10>=1,"Strong",IF(B10>=0.5,"Good",IF(B10>=0,"Weak","Negative"))) | E10: Excess return per unit of total risk. Above 0.5 is good for a diversified portfolio, above 1 is rare over long periods.
A11: Sortino ratio | B11: =IFERROR(AVERAGE(History!$H$6:$H$185)*12/(SQRT(SUM(History!$O$6:$O$185)/COUNT(History!$O$6:$O$185))*SQRT(12)),0) | E11: Like Sharpe, but only penalises downside volatility.
A12: Maximum drawdown | B12: =IFERROR(MIN(History!$M$6:$M$185),0) | C12: =IFERROR(MIN(History!$N$6:$N$185),0) | D12: =IF(B12<C12,"Deeper than benchmark","Shallower than benchmark") | E12: Largest fall from a peak to a later trough (month-end data, so intra-month falls can be deeper).
A13: Current drawdown | B13: =IFERROR(LOOKUP(2,1/(History!$M$6:$M$185<>""),History!$M$6:$M$185),0) | E13: Distance from the highest value reached so far.
A14: Calmar ratio | B14: =IFERROR(B7/ABS(B12),0) | C14: =IFERROR(C7/ABS(C12),0) | E14: Annualised return divided by the maximum drawdown.
A15: Historical VaR (monthly) | B15: =IFERROR(-PERCENTILE(History!$D$6:$D$185,1-Settings!$B$9),0) | C15: =IFERROR(-PERCENTILE(History!$F$6:$F$185,1-Settings!$B$9),0) | D15: =IF(B15>C15,"Riskier than benchmark","Less risky than benchmark") | E15: Monthly loss not exceeded in the chosen share of months (Settings!B9). A 95 % VaR of 5 % means one month in twenty loses more than 5 %.
A16: Expected Shortfall (monthly) | B16: =IFERROR(-AVERAGEIF(History!$D$6:$D$185,"<="&-B15),0) | C16: =IFERROR(-AVERAGEIF(History!$F$6:$F$185,"<="&-C15),0) | E16: Average loss in the months worse than the VaR. Captures how deep the bad months are.
A17: Parametric VaR (monthly, normal) | B17: =IFERROR(-(AVERAGE(History!$D$6:$D$185)+NORMSINV(1-Settings!$B$9)*STDEV(History!$D$6:$D$185)),0) | E17: VaR assuming normally distributed returns. If it is below the historical VaR, losses have fatter tails than a normal law.
A18: VaR in euros (monthly) | B18: =B15*Dashboard!$B$6 | E18: Historical VaR applied to today's portfolio value.
A19: ES in euros (monthly) | B19: =B16*Dashboard!$B$6 | E19: Expected Shortfall applied to today's portfolio value.
A20: Beta vs benchmark | B20: =IFERROR(SLOPE(History!$D$6:$D$185,History!$F$6:$F$185),0) | C20: 1 | E20: Sensitivity to the benchmark: 0.7 means the portfolio moves 0.7 % when the benchmark moves 1 %.
A21: Correlation vs benchmark | B21: =IFERROR(CORREL(History!$D$6:$D$185,History!$F$6:$F$185),0) | C21: 1 | D21: =IF(B21>0.9,"Very close to index",IF(B21>0.6,"Moderately diversified","Well diversified")) | E21: From −1 (opposite) to +1 (identical). Lower means more diversification.
A22: Jensen's alpha (annual) | B22: =IFERROR((AVERAGE(History!$H$6:$H$185)-B20*AVERAGE(History!$I$6:$I$185))*12,0) | E22: Return above what the beta alone would explain.
A23: Tracking error | B23: =IFERROR(STDEV(History!$J$6:$J$185)*SQRT(12),0) | E23: Volatility of the difference with the benchmark. How far the portfolio strays from it.
A24: Information ratio | B24: =IFERROR(AVERAGE(History!$J$6:$J$185)*12/B23,0) | E24: Active return per unit of tracking error. Above 0.5 is good.
A25: Up-capture | B25: =IFERROR(AVERAGEIF(History!$F$6:$F$185,">0",History!$D$6:$D$185)/AVERAGEIF(History!$F$6:$F$185,">0"),0) | E25: Share of the benchmark's rising months captured.
A26: Down-capture | B26: =IFERROR(AVERAGEIF(History!$F$6:$F$185,"<0",History!$D$6:$D$185)/AVERAGEIF(History!$F$6:$F$185,"<0"),0) | E26: Share of the benchmark's falling months suffered. Below 100 % is what diversification aims for.
A27: Positive months | B27: =IFERROR(COUNTIF(History!$D$6:$D$185,">0")/COUNT(History!$D$6:$D$185),0) | C27: =IFERROR(COUNTIF(History!$F$6:$F$185,">0")/COUNT(History!$F$6:$F$185),0) | E27: Share of months with a gain.
A28: Best month | B28: =IFERROR(MAX(History!$D$6:$D$185),0) | C28: =IFERROR(MAX(History!$F$6:$F$185),0)
A29: Worst month | B29: =IFERROR(MIN(History!$D$6:$D$185),0) | C29: =IFERROR(MIN(History!$F$6:$F$185),0)
A30: Skewness | B30: =IFERROR(SKEW(History!$D$6:$D$185),0) | C30: =IFERROR(SKEW(History!$F$6:$F$185),0) | E30: Negative = more large losses than large gains (typical of equities).
A31: Excess kurtosis | B31: =IFERROR(KURT(History!$D$6:$D$185),0) | C31: =IFERROR(KURT(History!$F$6:$F$185),0) | E31: Above 0 = fatter tails than a normal distribution.
A32: Concentration (HHI) | B32: =SUMSQ(Holdings!$L$8:$L$47)+Holdings!$L$49^2 | E32: Sum of squared weights. 1/HHI = effective number of positions.
A33: Effective number of positions | B33: =IFERROR(1/B32,0) | E33: Number of equally weighted positions with the same concentration.
A34: Top-3 weight | B34: =IFERROR(SUMPRODUCT(LARGE(Holdings!$L$8:$L$47,{1,2,3})),SUM(Holdings!$L$8:$L$47)) | E34: Weight of the three largest positions.
A35: Cash weight | B35: =Holdings!$L$49 | E35: Share of the portfolio held in cash (money-market ETFs count as positions).
A36: Fees paid (total) | B36: =SUM(Transactions!$H$6:$H$505)+SUMIFS(Transactions!$J$6:$J$505,Transactions!$B$6:$B$505,"Fee") | E36: Transaction fees plus platform fees since inception.
A37: Dividends received (total) | B37: =SUMIFS(Transactions!$J$6:$J$505,Transactions!$B$6:$B$505,"Dividend") | E37: Cash dividends logged in Transactions.

Sheet Allocation
A1: Allocation
A2: Actual weights from Holdings (cash included) compared with targets.
A4: By asset class
A5: Group | B5: Value (EUR) | C5: Weight
A6: Equity | B6: =SUMIFS(Holdings!$K$8:$K$47,Holdings!$C$8:$C$47,A6) | C6: =IFERROR(B6/Holdings!$B$5,0)
A7: Bond | B7: =SUMIFS(Holdings!$K$8:$K$47,Holdings!$C$8:$C$47,A7) | C7: =IFERROR(B7/Holdings!$B$5,0)
A8: Commodity | B8: =SUMIFS(Holdings!$K$8:$K$47,Holdings!$C$8:$C$47,A8) | C8: =IFERROR(B8/Holdings!$B$5,0)
A9: Money market | B9: =SUMIFS(Holdings!$K$8:$K$47,Holdings!$C$8:$C$47,A9) | C9: =IFERROR(B9/Holdings!$B$5,0)
A10: Other | B10: =SUMIFS(Holdings!$K$8:$K$47,Holdings!$C$8:$C$47,A10) | C10: =IFERROR(B10/Holdings!$B$5,0)
A11: Cash | B11: =Holdings!$B$4 | C11: =IFERROR(B11/Holdings!$B$5,0)
A12: Total | B12: =SUM(B6:B11) | C12: =SUM(C6:C11)
A14: By strategy
A15: Group | B15: Value (EUR) | C15: Weight | D15: Target | E15: Deviation
A16: =Settings!A15 | B16: =SUMIFS(Holdings!$K$8:$K$47,Holdings!$D$8:$D$47,A16) | C16: =IFERROR(B16/Holdings!$B$5,0) | D16: =Settings!B15 | E16: =C16-D16
